[2024-08-28T09:19:36.346+0000] {local_task_job_runner.py:123} INFO - ::group::Pre task execution logs
[2024-08-28T09:19:36.376+0000] {taskinstance.py:2603} INFO - Dependencies all met for dep_context=non-requeueable deps ti=<TaskInstance: dag_with_postgres_operator.insert_into_table scheduled__2024-08-25T00:00:00+00:00 [queued]>
[2024-08-28T09:19:36.388+0000] {taskinstance.py:2603} INFO - Dependencies all met for dep_context=requeueable deps ti=<TaskInstance: dag_with_postgres_operator.insert_into_table scheduled__2024-08-25T00:00:00+00:00 [queued]>
[2024-08-28T09:19:36.389+0000] {taskinstance.py:2856} INFO - Starting attempt 6 of 6
[2024-08-28T09:19:36.410+0000] {taskinstance.py:2879} INFO - Executing <Task(PostgresOperator): insert_into_table> on 2024-08-25 00:00:00+00:00
[2024-08-28T09:19:36.420+0000] {warnings.py:112} WARNING - /home/***/.local/lib/python3.12/site-packages/***/task/task_runner/standard_task_runner.py:70: DeprecationWarning: This process (pid=1425) is multi-threaded, use of fork() may lead to deadlocks in the child.
  pid = os.fork()

[2024-08-28T09:19:36.423+0000] {standard_task_runner.py:72} INFO - Started process 1435 to run task
[2024-08-28T09:19:36.423+0000] {standard_task_runner.py:104} INFO - Running: ['***', 'tasks', 'run', 'dag_with_postgres_operator', 'insert_into_table', 'scheduled__2024-08-25T00:00:00+00:00', '--job-id', '90', '--raw', '--subdir', 'DAGS_FOLDER/postgres-demo.py', '--cfg-path', '/tmp/tmp6bws_2hl']
[2024-08-28T09:19:36.424+0000] {standard_task_runner.py:105} INFO - Job 90: Subtask insert_into_table
[2024-08-28T09:19:36.492+0000] {task_command.py:467} INFO - Running <TaskInstance: dag_with_postgres_operator.insert_into_table scheduled__2024-08-25T00:00:00+00:00 [running]> on host 2d2e6ae1efc8
[2024-08-28T09:19:36.618+0000] {taskinstance.py:3122} INFO - Exporting env vars: AIRFLOW_CTX_DAG_OWNER='asukhikh' AIRFLOW_CTX_DAG_ID='dag_with_postgres_operator' AIRFLOW_CTX_TASK_ID='insert_into_table' AIRFLOW_CTX_EXECUTION_DATE='2024-08-25T00:00:00+00:00' AIRFLOW_CTX_TRY_NUMBER='6' AIRFLOW_CTX_DAG_RUN_ID='scheduled__2024-08-25T00:00:00+00:00'
[2024-08-28T09:19:36.622+0000] {logging_mixin.py:190} INFO - Task instance is in running state
[2024-08-28T09:19:36.624+0000] {logging_mixin.py:190} INFO -  Previous state of the Task instance: queued
[2024-08-28T09:19:36.625+0000] {logging_mixin.py:190} INFO - Current task name:insert_into_table state:running start_date:2024-08-28 09:19:36.377098+00:00
[2024-08-28T09:19:36.626+0000] {logging_mixin.py:190} INFO - Dag name:dag_with_postgres_operator and current dag run status:running
[2024-08-28T09:19:36.627+0000] {taskinstance.py:731} INFO - ::endgroup::
[2024-08-28T09:19:36.628+0000] {sql.py:282} INFO - Executing: 
            INSERT INTO Orders
            SELECT 
                floor(random() * 10) as OrderID,
                (array['created', 'in transit', 'delivered'])[floor(random() * 3 + 1)] as Status
            FROM generate_series(1, 1)
        
[2024-08-28T09:19:36.642+0000] {base.py:84} INFO - Retrieving connection 'postgres_local'
[2024-08-28T09:19:36.662+0000] {base.py:84} INFO - Retrieving connection 'postgres_local'
[2024-08-28T09:19:36.718+0000] {sql.py:509} INFO - Running statement: 
            INSERT INTO Orders
            SELECT 
                floor(random() * 10) as OrderID,
                (array['created', 'in transit', 'delivered'])[floor(random() * 3 + 1)] as Status
            FROM generate_series(1, 1)
        , parameters: None
[2024-08-28T09:19:36.725+0000] {taskinstance.py:3301} ERROR - Task failed with exception
Traceback (most recent call last):
  File "/home/airflow/.local/lib/python3.12/site-packages/airflow/models/taskinstance.py", line 767, in _execute_task
    result = _execute_callable(context=context, **execute_callable_kwargs)
             ^^^^^^^^^^^^^^^^^^^^^^^^^^^^^^^^^^^^^^^^^^^^^^^^^^^^^^^^^^^^^
  File "/home/airflow/.local/lib/python3.12/site-packages/airflow/models/taskinstance.py", line 733, in _execute_callable
    return ExecutionCallableRunner(
           ^^^^^^^^^^^^^^^^^^^^^^^^
  File "/home/airflow/.local/lib/python3.12/site-packages/airflow/utils/operator_helpers.py", line 252, in run
    return self.func(*args, **kwargs)
           ^^^^^^^^^^^^^^^^^^^^^^^^^^
  File "/home/airflow/.local/lib/python3.12/site-packages/airflow/models/baseoperator.py", line 406, in wrapper
    return func(self, *args, **kwargs)
           ^^^^^^^^^^^^^^^^^^^^^^^^^^^
  File "/home/airflow/.local/lib/python3.12/site-packages/airflow/providers/common/sql/operators/sql.py", line 288, in execute
    output = hook.run(
             ^^^^^^^^^
  File "/home/airflow/.local/lib/python3.12/site-packages/airflow/providers/common/sql/hooks/sql.py", line 456, in run
    self._run_command(cur, sql_statement, parameters)
  File "/home/airflow/.local/lib/python3.12/site-packages/airflow/providers/common/sql/hooks/sql.py", line 514, in _run_command
    cur.execute(sql_statement)
psycopg2.errors.UndefinedTable: relation "orders" does not exist
LINE 2:             INSERT INTO Orders
                                ^

[2024-08-28T09:19:36.765+0000] {logging_mixin.py:190} INFO - Task instance in failure state
[2024-08-28T09:19:36.767+0000] {logging_mixin.py:190} INFO - Task start:2024-08-28 09:19:36.377098+00:00 end:2024-08-28 09:19:36.765016+00:00 duration:0.387918
[2024-08-28T09:19:36.768+0000] {logging_mixin.py:190} INFO - Task:<Task(PostgresOperator): insert_into_table> dag:<DAG: dag_with_postgres_operator> dagrun:<DagRun dag_with_postgres_operator @ 2024-08-25 00:00:00+00:00: scheduled__2024-08-25T00:00:00+00:00, state:running, queued_at: 2024-08-28 09:11:21.089755+00:00. externally triggered: False>
[2024-08-28T09:19:36.771+0000] {logging_mixin.py:190} INFO - Failure caused by relation "orders" does not exist
LINE 2:             INSERT INTO Orders
                                ^
[2024-08-28T09:19:36.774+0000] {taskinstance.py:1225} INFO - Marking task as FAILED. dag_id=dag_with_postgres_operator, task_id=insert_into_table, run_id=scheduled__2024-08-25T00:00:00+00:00, execution_date=20240825T000000, start_date=20240828T091936, end_date=20240828T091936
[2024-08-28T09:19:36.812+0000] {taskinstance.py:340} INFO - ::group::Post task execution logs
[2024-08-28T09:19:36.815+0000] {standard_task_runner.py:124} ERROR - Failed to execute job 90 for task insert_into_table (relation "orders" does not exist
LINE 2:             INSERT INTO Orders
                                ^
; 1435)
Traceback (most recent call last):
  File "/home/airflow/.local/lib/python3.12/site-packages/airflow/task/task_runner/standard_task_runner.py", line 117, in _start_by_fork
    ret = args.func(args, dag=self.dag)
          ^^^^^^^^^^^^^^^^^^^^^^^^^^^^^
  File "/home/airflow/.local/lib/python3.12/site-packages/airflow/cli/cli_config.py", line 49, in command
    return func(*args, **kwargs)
           ^^^^^^^^^^^^^^^^^^^^^
  File "/home/airflow/.local/lib/python3.12/site-packages/airflow/utils/cli.py", line 115, in wrapper
    return f(*args, **kwargs)
           ^^^^^^^^^^^^^^^^^^
  File "/home/airflow/.local/lib/python3.12/site-packages/airflow/cli/commands/task_command.py", line 483, in task_run
    task_return_code = _run_task_by_selected_method(args, _dag, ti)
                       ^^^^^^^^^^^^^^^^^^^^^^^^^^^^^^^^^^^^^^^^^^^^
  File "/home/airflow/.local/lib/python3.12/site-packages/airflow/cli/commands/task_command.py", line 256, in _run_task_by_selected_method
    return _run_raw_task(args, ti)
           ^^^^^^^^^^^^^^^^^^^^^^^
  File "/home/airflow/.local/lib/python3.12/site-packages/airflow/cli/commands/task_command.py", line 341, in _run_raw_task
    return ti._run_raw_task(
           ^^^^^^^^^^^^^^^^^
  File "/home/airflow/.local/lib/python3.12/site-packages/airflow/utils/session.py", line 97, in wrapper
    return func(*args, session=session, **kwargs)
           ^^^^^^^^^^^^^^^^^^^^^^^^^^^^^^^^^^^^^^
  File "/home/airflow/.local/lib/python3.12/site-packages/airflow/models/taskinstance.py", line 2995, in _run_raw_task
    return _run_raw_task(
           ^^^^^^^^^^^^^^
  File "/home/airflow/.local/lib/python3.12/site-packages/airflow/models/taskinstance.py", line 273, in _run_raw_task
    TaskInstance._execute_task_with_callbacks(
  File "/home/airflow/.local/lib/python3.12/site-packages/airflow/models/taskinstance.py", line 3149, in _execute_task_with_callbacks
    result = self._execute_task(context, task_orig)
             ^^^^^^^^^^^^^^^^^^^^^^^^^^^^^^^^^^^^^^
  File "/home/airflow/.local/lib/python3.12/site-packages/airflow/models/taskinstance.py", line 3173, in _execute_task
    return _execute_task(self, context, task_orig)
           ^^^^^^^^^^^^^^^^^^^^^^^^^^^^^^^^^^^^^^^
  File "/home/airflow/.local/lib/python3.12/site-packages/airflow/models/taskinstance.py", line 767, in _execute_task
    result = _execute_callable(context=context, **execute_callable_kwargs)
             ^^^^^^^^^^^^^^^^^^^^^^^^^^^^^^^^^^^^^^^^^^^^^^^^^^^^^^^^^^^^^
  File "/home/airflow/.local/lib/python3.12/site-packages/airflow/models/taskinstance.py", line 733, in _execute_callable
    return ExecutionCallableRunner(
           ^^^^^^^^^^^^^^^^^^^^^^^^
  File "/home/airflow/.local/lib/python3.12/site-packages/airflow/utils/operator_helpers.py", line 252, in run
    return self.func(*args, **kwargs)
           ^^^^^^^^^^^^^^^^^^^^^^^^^^
  File "/home/airflow/.local/lib/python3.12/site-packages/airflow/models/baseoperator.py", line 406, in wrapper
    return func(self, *args, **kwargs)
           ^^^^^^^^^^^^^^^^^^^^^^^^^^^
  File "/home/airflow/.local/lib/python3.12/site-packages/airflow/providers/common/sql/operators/sql.py", line 288, in execute
    output = hook.run(
             ^^^^^^^^^
  File "/home/airflow/.local/lib/python3.12/site-packages/airflow/providers/common/sql/hooks/sql.py", line 456, in run
    self._run_command(cur, sql_statement, parameters)
  File "/home/airflow/.local/lib/python3.12/site-packages/airflow/providers/common/sql/hooks/sql.py", line 514, in _run_command
    cur.execute(sql_statement)
psycopg2.errors.UndefinedTable: relation "orders" does not exist
LINE 2:             INSERT INTO Orders
                                ^

[2024-08-28T09:19:36.920+0000] {local_task_job_runner.py:261} INFO - Task exited with return code 1
[2024-08-28T09:19:36.937+0000] {warnings.py:112} WARNING - /home/***/.local/lib/python3.12/site-packages/***/models/baseoperator.py:1378: AirflowProviderDeprecationWarning: Call to deprecated class PostgresOperator. (Please use `***.providers.common.sql.operators.sql.SQLExecuteQueryOperator`.Also, you can provide `hook_params={'schema': <database>}`.)
  result = cls.__new__(cls)

[2024-08-28T09:19:36.966+0000] {taskinstance.py:3891} INFO - 0 downstream tasks scheduled from follow-on schedule check
[2024-08-28T09:19:36.976+0000] {local_task_job_runner.py:240} INFO - ::endgroup::
